<?xml version="1.0" encoding="utf-8"?>
<!-- This URDF was automatically created by SolidWorks to URDF Exporter! Originally created by Stephen Brawner (brawner@gmail.com) 
     Commit Version: 1.6.0-4-g7f85cfe  Build Version: 1.6.7995.38578
     For more information, please see http://wiki.ros.org/sw_urdf_exporter -->
<robot
  name="as1">
  <link
    name="base_link">
    <inertial>
      <origin
        xyz="-0.0233673684020749 0.00375946264305613 -0.105963322965588"
        rpy="0 0 0" />
      <mass
        value="5.21419137667796" />
      <inertia
        ixx="0.0598529347517588"
        ixy="0.00107694936404555"
        ixz="0.00436850451811629"
        iyy="0.0817267703320559"
        iyz="0.000263568538641487"
        izz="0.1120238626061" />
    </inertial>
    <visual>
      <origin
        xyz="0 0 0"
        rpy="0 0 0" />
      <geometry>
        <mesh
          filename="package://as1/meshes/base_link.STL" />
      </geometry>
      <material
        name="">
        <color
          rgba="0.792156862745098 0.819607843137255 0.933333333333333 1" />
      </material>
    </visual>
    <collision>
      <origin
        xyz="0 0 0"
        rpy="0 0 0" />
      <geometry>
        <mesh
          filename="package://as1/meshes/base_link.STL" />
      </geometry>
    </collision>
  </link>
  <link
    name="link_1">
    <inertial>
      <origin
        xyz="0.0104492747595369 0.0238190656714165 0.126003219412791"
        rpy="0 0 0" />
      <mass
        value="18.9644281612299" />
      <inertia
        ixx="0.334615058691766"
        ixy="0.0272075098638983"
        ixz="-0.0126072885949166"
        iyy="0.345495178002126"
        iyz="-0.0410445221132301"
        izz="0.30546212847528" />
    </inertial>
    <visual>
      <origin
        xyz="0 0 0"
        rpy="0 0 0" />
      <geometry>
        <mesh
          filename="package://as1/meshes/link_1.STL" />
      </geometry>
      <material
        name="">
        <color
          rgba="0.792156862745098 0.819607843137255 0.933333333333333 1" />
      </material>
    </visual>
    <collision>
      <origin
        xyz="0 0 0"
        rpy="0 0 0" />
      <geometry>
        <mesh
          filename="package://as1/meshes/link_1.STL" />
      </geometry>
    </collision>
  </link>
  <joint
    name="joint1"
    type="revolute">
    <origin
      xyz="0 0 0"
      rpy="0 0 0" />
    <parent
      link="base_link" />
    <child
      link="link_1" />
    <axis
      xyz="0 0 -1" />
    <limit
      lower="-3.1416"
      upper="3.1416"
      effort="100"
      velocity="2" />
  </joint>
  <link
    name="link_2">
    <inertial>
      <origin
        xyz="-0.0923614117299397 -0.0808864455716424 0.344791779973973"
        rpy="0 0 0" />
      <mass
        value="20.7425365417751" />
      <inertia
        ixx="1.87563964620917"
        ixy="-0.0179379854284755"
        ixz="0.290357094787437"
        iyy="1.96341576264713"
        iyz="-0.0268209589565669"
        izz="0.169078492834354" />
    </inertial>
    <visual>
      <origin
        xyz="0 0 0"
        rpy="0 0 0" />
      <geometry>
        <mesh
          filename="package://as1/meshes/link_2.STL" />
      </geometry>
      <material
        name="">
        <color
          rgba="0.792156862745098 0.819607843137255 0.933333333333333 1" />
      </material>
    </visual>
    <collision>
      <origin
        xyz="0 0 0"
        rpy="0 0 0" />
      <geometry>
        <mesh
          filename="package://as1/meshes/link_2.STL" />
      </geometry>
    </collision>
  </link>
  <joint
    name="joint2"
    type="revolute">
    <origin
      xyz="0.078984 -0.10635 0.21973"
      rpy="0 0 0" />
    <parent
      link="link_1" />
    <child
      link="link_2" />
    <axis
      xyz="0 -1 0" />
    <limit
      lower="-1.5708"
      upper="1.5708"
      effort="100"
      velocity="2" />
  </joint>
  <link
    name="link_3">
    <inertial>
      <origin
        xyz="0.136575788044544 0.117268659899779 0.113378625216662"
        rpy="0 0 0" />
      <mass
        value="13.4512374849002" />
      <inertia
        ixx="0.224055463288954"
        ixy="-0.0121850892901722"
        ixz="-0.0956286765812692"
        iyy="0.275927612709498"
        iyz="-0.00527745613866116"
        izz="0.215613728805979" />
    </inertial>
    <visual>
      <origin
        xyz="0 0 0"
        rpy="0 0 0" />
      <geometry>
        <mesh
          filename="package://as1/meshes/link_3.STL" />
      </geometry>
      <material
        name="">
        <color
          rgba="0.792156862745098 0.819607843137255 0.933333333333333 1" />
      </material>
    </visual>
    <collision>
      <origin
        xyz="0 0 0"
        rpy="0 0 0" />
      <geometry>
        <mesh
          filename="package://as1/meshes/link_3.STL" />
      </geometry>
    </collision>
  </link>
  <joint
    name="joint3"
    type="revolute">
    <origin
      xyz="-0.11596 0.020379 0.83207"
      rpy="0 0 0" />
    <parent
      link="link_2" />
    <child
      link="link_3" />
    <axis
      xyz="0 -1 0" />
    <limit
      lower="-1.5708"
      upper="1.5708"
      effort="100"
      velocity="2" />
  </joint>
  <link
    name="link_4">
    <inertial>
      <origin
        xyz="0.501134425880994 -0.00428964990754252 0.00155670376564077"
        rpy="0 0 0" />
      <mass
        value="11.2572274332167" />
      <inertia
        ixx="0.0277470668766059"
        ixy="0.0505294926419451"
        ixz="-0.00742649894191705"
        iyy="0.935689886130332"
        iyz="0.000673138359578124"
        izz="0.941813414197717" />
    </inertial>
    <visual>
      <origin
        xyz="0 0 0"
        rpy="0 0 0" />
      <geometry>
        <mesh
          filename="package://as1/meshes/link_4.STL" />
      </geometry>
      <material
        name="">
        <color
          rgba="0.792156862745098 0.819607843137255 0.933333333333333 1" />
      </material>
    </visual>
    <collision>
      <origin
        xyz="0 0 0"
        rpy="0 0 0" />
      <geometry>
        <mesh
          filename="package://as1/meshes/link_4.STL" />
      </geometry>
    </collision>
  </link>
  <joint
    name="joint4"
    type="revolute">
    <origin
      xyz="0.29158 0.090386 0.21469"
      rpy="0 0 0" />
    <parent
      link="link_3" />
    <child
      link="link_4" />
    <axis
      xyz="1 0 0" />
    <limit
      lower="-3.1416"
      upper="3.1416"
      effort="100"
      velocity="2" />
  </joint>
  <link
    name="end_link">
    <inertial>
      <origin
        xyz="0.2259771378748 0.0624580233555173 0.0448242124362421"
        rpy="0 0 0" />
      <mass
        value="1.76534714271895" />
      <inertia
        ixx="0.00281408448832343"
        ixy="-0.000215380883179021"
        ixz="-7.8042969186613E-05"
        iyy="0.00298968198332777"
        iyz="-3.36562530876571E-05"
        izz="0.00266081663711982" />
    </inertial>
    <visual>
      <origin
        xyz="0 0 0"
        rpy="0 0 0" />
      <geometry>
        <mesh
          filename="package://as1/meshes/end_link.STL" />
      </geometry>
      <material
        name="">
        <color
          rgba="0.792156862745098 0.819607843137255 0.933333333333333 1" />
      </material>
    </visual>
    <collision>
      <origin
        xyz="0 0 0"
        rpy="0 0 0" />
      <geometry>
        <mesh
          filename="package://as1/meshes/end_link.STL" />
      </geometry>
    </collision>
  </link>
  <joint
    name="end_joint"
    type="revolute">
    <origin
      xyz="1.0455 -0.007287 0.0040489"
      rpy="0 0 0" />
    <parent
      link="link_4" />
    <child
      link="end_link" />
    <axis
      xyz="0 1 0" />
    <limit
      lower="-1.5708"
      upper="1.5708"
      effort="100"
      velocity="2" />
  </joint>
</robot>
