<?xml version="1.0" encoding="utf-8"?>
<!-- This URDF was automatically created by SolidWorks to URDF Exporter! Originally created by Stephen Brawner (brawner@gmail.com) 
     Commit Version: 1.6.0-4-g7f85cfe  Build Version: 1.6.7995.38578
     For more information, please see http://wiki.ros.org/sw_urdf_exporter -->
<robot
  name="robotas">
  <link
    name="base_link">
    <inertial>
      <origin
        xyz="-0.023367 0.0037595 -0.10596"
        rpy="0 0 0" />
      <mass
        value="5.2142" />
      <inertia
        ixx="0.059853"
        ixy="0.0010769"
        ixz="0.0043685"
        iyy="0.081727"
        iyz="0.00026357"
        izz="0.11202" />
    </inertial>
    <visual>
      <origin
        xyz="0 0 0"
        rpy="0 0 0" />
      <geometry>
        <mesh
          filename="package://robotas/meshes/base_link.STL" />
      </geometry>
      <material
        name="">
        <color
          rgba="0.79216 0.81961 0.93333 1" />
      </material>
    </visual>
    <collision>
      <origin
        xyz="0 0 0"
        rpy="0 0 0" />
      <geometry>
        <mesh
          filename="package://robotas/meshes/base_link.STL" />
      </geometry>
    </collision>
  </link>
  <link
    name="link_1">
    <inertial>
      <origin
        xyz="0.016371 0.020212 0.126"
        rpy="0 0 0" />
      <mass
        value="18.964" />
      <inertia
        ixx="0.34924"
        ixy="0.026181"
        ixz="-0.023004"
        iyy="0.33087"
        iyz="-0.036255"
        izz="0.30546" />
    </inertial>
    <visual>
      <origin
        xyz="0 0 0"
        rpy="0 0 0" />
      <geometry>
        <mesh
          filename="package://robotas/meshes/link_1.STL" />
      </geometry>
      <material
        name="">
        <color
          rgba="0.79216 0.81961 0.93333 1" />
      </material>
    </visual>
    <collision>
      <origin
        xyz="0 0 0"
        rpy="0 0 0" />
      <geometry>
        <mesh
          filename="package://robotas/meshes/link_1.STL" />
      </geometry>
    </collision>
  </link>
  <joint
    name="joint0"
    type="revolute">
    <origin
      xyz="0 0 0"
      rpy="0 0 0" />
    <parent
      link="base_link" />
    <child
      link="link_1" />
    <axis
      xyz="0 0 -1" />
    <limit
      lower="-3.1416"
      upper="3.1416"
      effort="100"
      velocity="2" />
  </joint>
  <link
    name="link_2">
    <inertial>
      <origin
        xyz="-0.15656 -0.042794 0.32804"
        rpy="0 0 0" />
      <mass
        value="20.743" />
      <inertia
        ixx="1.7673"
        ixy="0.037048"
        ixz="0.49181"
        iyy="1.9581"
        iyz="-0.15565"
        izz="0.28276" />
    </inertial>
    <visual>
      <origin
        xyz="0 0 0"
        rpy="0 0 0" />
      <geometry>
        <mesh
          filename="package://robotas/meshes/link_2.STL" />
      </geometry>
      <material
        name="">
        <color
          rgba="0.79216 0.81961 0.93333 1" />
      </material>
    </visual>
    <collision>
      <origin
        xyz="0 0 0"
        rpy="0 0 0" />
      <geometry>
        <mesh
          filename="package://robotas/meshes/link_2.STL" />
      </geometry>
    </collision>
  </link>
  <joint
    name="joint1"
    type="revolute">
    <origin
      xyz="0.048078 -0.12344 0.21973"
      rpy="0 0 0" />
    <parent
      link="link_1" />
    <child
      link="link_2" />
    <axis
      xyz="-0.22838 -0.97357 0" />
    <limit
      lower="-1.5708"
      upper="1.5708"
      effort="100"
      velocity="2" />
  </joint>
  <link
    name="link_3">
    <inertial>
      <origin
        xyz="0.16403 0.076707 0.11166"
        rpy="0 0 0" />
      <mass
        value="13.451" />
      <inertia
        ixx="0.21926"
        ixy="0.0032332"
        ixz="-0.093659"
        iyy="0.2784"
        iyz="0.020311"
        izz="0.21793" />
    </inertial>
    <visual>
      <origin
        xyz="0 0 0"
        rpy="0 0 0" />
      <geometry>
        <mesh
          filename="package://robotas/meshes/link_3.STL" />
      </geometry>
      <material
        name="">
        <color
          rgba="0.79216 0.81961 0.93333 1" />
      </material>
    </visual>
    <collision>
      <origin
        xyz="0 0 0"
        rpy="0 0 0" />
      <geometry>
        <mesh
          filename="package://robotas/meshes/link_3.STL" />
      </geometry>
    </collision>
  </link>
  <joint
    name="joint2"
    type="revolute">
    <origin
      xyz="-0.21883 0.076652 0.80774"
      rpy="0 0 0" />
    <parent
      link="link_2" />
    <child
      link="link_3" />
    <axis
      xyz="-0.22838 -0.97357 0" />
    <limit
      lower="-3.1416"
      upper="3.1416"
      effort="100"
      velocity="2" />
  </joint>
  <link
    name="link_4">
    <inertial>
      <origin
        xyz="0.48898 -0.10868 0.015545"
        rpy="0 0 0" />
      <mass
        value="11.257" />
      <inertia
        ixx="0.068312"
        ixy="0.18244"
        ixz="-0.06822"
        iyy="0.90358"
        iyz="0.013423"
        izz="0.93336" />
    </inertial>
    <visual>
      <origin
        xyz="0 0 0"
        rpy="0 0 0" />
      <geometry>
        <mesh
          filename="package://robotas/meshes/link_4.STL" />
      </geometry>
      <material
        name="">
        <color
          rgba="0.79216 0.81961 0.93333 1" />
      </material>
    </visual>
    <collision>
      <origin
        xyz="0 0 0"
        rpy="0 0 0" />
      <geometry>
        <mesh
          filename="package://robotas/meshes/link_4.STL" />
      </geometry>
    </collision>
  </link>
  <joint
    name="joint3"
    type="revolute">
    <origin
      xyz="0.30761 0.0095485 0.21111"
      rpy="0 0 0" />
    <parent
      link="link_3" />
    <child
      link="link_4" />
    <axis
      xyz="0.97349 -0.22836 -0.013158" />
    <limit
      lower="-1.5708"
      upper="1.5708"
      effort="100"
      velocity="2" />
  </joint>
  <link
    name="link_5">
    <inertial>
      <origin
        xyz="0.021696 -0.014484 -0.034944"
        rpy="0 0 0" />
      <mass
        value="0.36782" />
      <inertia
        ixx="0.00070285"
        ixy="5.6091E-05"
        ixz="0.00018674"
        iyy="0.00068677"
        iyz="-4.4138E-05"
        izz="0.00068567" />
    </inertial>
    <visual>
      <origin
        xyz="0 0 0"
        rpy="0 0 0" />
      <geometry>
        <mesh
          filename="package://robotas/meshes/link_5.STL" />
      </geometry>
      <material
        name="">
        <color
          rgba="0.79216 0.81961 0.93333 1" />
      </material>
    </visual>
    <collision>
      <origin
        xyz="0 0 0"
        rpy="0 0 0" />
      <geometry>
        <mesh
          filename="package://robotas/meshes/link_5.STL" />
      </geometry>
    </collision>
  </link>
  <joint
    name="joint4"
    type="revolute">
    <origin
      xyz="1.0212 -0.22313 0.041903"
      rpy="0 0 0" />
    <parent
      link="link_4" />
    <child
      link="link_5" />
    <axis
      xyz="-0.075349 -0.26583 -0.96107" />
    <limit
      lower="-3.1416"
      upper="3.1416"
      effort="100"
      velocity="2" />
  </joint>
  <link
    name="link_6">
    <inertial>
      <origin
        xyz="-0.0088492 0.001802 0.00019536"
        rpy="0 0 0" />
      <mass
        value="0.15001" />
      <inertia
        ixx="0.00030556"
        ixy="-2.9517E-05"
        ixz="-3.2336E-06"
        iyy="0.00016664"
        iyz="4.9348E-07"
        izz="0.00016061" />
    </inertial>
    <visual>
      <origin
        xyz="0 0 0"
        rpy="0 0 0" />
      <geometry>
        <mesh
          filename="package://robotas/meshes/link_6.STL" />
      </geometry>
      <material
        name="">
        <color
          rgba="0.79216 0.81961 0.93333 1" />
      </material>
    </visual>
    <collision>
      <origin
        xyz="0 0 0"
        rpy="0 0 0" />
      <geometry>
        <mesh
          filename="package://robotas/meshes/link_6.STL" />
      </geometry>
    </collision>
  </link>
  <joint
    name="joint5"
    type="fixed">
    <origin
      xyz="0.08239 -0.032861 -0.056887"
      rpy="0 0 0" />
    <parent
      link="link_5" />
    <child
      link="link_6" />
    <axis
      xyz="0 0 0" />
  </joint>
  <link
    name="link_7">
    <inertial>
      <origin
        xyz="0.047638 -0.010107 -0.00376"
        rpy="0 0 0" />
      <mass
        value="0.34805" />
      <inertia
        ixx="0.00062726"
        ixy="2.6989E-05"
        ixz="5.3511E-06"
        iyy="0.00075016"
        iyz="3.1984E-06"
        izz="0.00078311" />
    </inertial>
    <visual>
      <origin
        xyz="0 0 0"
        rpy="0 0 0" />
      <geometry>
        <mesh
          filename="package://robotas/meshes/link_7.STL" />
      </geometry>
      <material
        name="">
        <color
          rgba="0.79216 0.81961 0.93333 1" />
      </material>
    </visual>
    <collision>
      <origin
        xyz="0 0 0"
        rpy="0 0 0" />
      <geometry>
        <mesh
          filename="package://robotas/meshes/link_7.STL" />
      </geometry>
    </collision>
  </link>
  <joint
    name="joint6"
    type="fixed">
    <origin
      xyz="0.0014695 -0.00029924 -3.2441E-05"
      rpy="0 0 0" />
    <parent
      link="link_6" />
    <child
      link="link_7" />
    <axis
      xyz="0 0 0" />
  </joint>
  <link
    name="link_8">
    <inertial>
      <origin
        xyz="0.074346 -0.011933 0.022108"
        rpy="0 0 0" />
      <mass
        value="0.43567" />
      <inertia
        ixx="0.0004968"
        ixy="-7.8813E-07"
        ixz="-0.00011796"
        iyy="0.00057414"
        iyz="6.4768E-06"
        izz="0.0004441" />
    </inertial>
    <visual>
      <origin
        xyz="0 0 0"
        rpy="0 0 0" />
      <geometry>
        <mesh
          filename="package://robotas/meshes/link_8.STL" />
      </geometry>
      <material
        name="">
        <color
          rgba="0.6 0.6 0.6 1" />
      </material>
    </visual>
    <collision>
      <origin
        xyz="0 0 0"
        rpy="0 0 0" />
      <geometry>
        <mesh
          filename="package://robotas/meshes/link_8.STL" />
      </geometry>
    </collision>
  </link>
  <joint
    name="joint7"
    type="fixed">
    <origin
      xyz="0.096986 -0.01975 -0.0021411"
      rpy="0 0 0" />
    <parent
      link="link_7" />
    <child
      link="link_8" />
    <axis
      xyz="0 0 0" />
  </joint>
  <link
    name="end_link">
    <inertial>
      <origin
        xyz="0.031592 -0.0039015 0.01808"
        rpy="0 0 0" />
      <mass
        value="0.46379" />
      <inertia
        ixx="0.00070224"
        ixy="2.6501E-05"
        ixz="8.6964E-06"
        iyy="0.00081599"
        iyz="-3.8191E-05"
        izz="0.00056244" />
    </inertial>
    <visual>
      <origin
        xyz="0 0 0"
        rpy="0 0 0" />
      <geometry>
        <mesh
          filename="package://robotas/meshes/end_link.STL" />
      </geometry>
      <material
        name="">
        <color
          rgba="0.2 0.2 0.2 1" />
      </material>
    </visual>
    <collision>
      <origin
        xyz="0 0 0"
        rpy="0 0 0" />
      <geometry>
        <mesh
          filename="package://robotas/meshes/end_link.STL" />
      </geometry>
    </collision>
  </link>
  <joint
    name="end_joint"
    type="fixed">
    <origin
      xyz="0.24645 -0.025016 0.17975"
      rpy="0 0 0" />
    <parent
      link="link_8" />
    <child
      link="end_link" />
    <axis
      xyz="0 0 0" />
  </joint>
</robot>